Unable to init server: Could not connect: Connection refused
Unable to init server: Impossible de se connecter : Connection refused

(main.py:49552): Gdk-CRITICAL **: 12:28:56.587: gdk_cursor_new_for_display: assertion 'GDK_IS_DISPLAY (display)' failed
  0%|          | 0/1337 [00:00<?, ?it/s]  0%|          | 1/1337 [00:42<15:47:11, 42.54s/it]  0%|          | 2/1337 [00:43<6:38:33, 17.91s/it]   0%|          | 3/1337 [00:43<3:42:21, 10.00s/it]  0%|          | 4/1337 [00:44<2:19:34,  6.28s/it]  0%|          | 5/1337 [00:44<1:33:51,  4.23s/it]  0%|          | 6/1337 [00:45<1:06:16,  2.99s/it]  1%|          | 7/1337 [00:46<48:49,  2.20s/it]    1%|          | 8/1337 [00:46<37:22,  1.69s/it]  1%|          | 9/1337 [00:47<33:09,  1.50s/it]  1%|          | 10/1337 [00:58<1:36:22,  4.36s/it]  1%|          | 11/1337 [01:00<1:19:14,  3.59s/it]  1%|          | 12/1337 [01:01<1:01:19,  2.78s/it]  1%|          | 13/1337 [01:04<1:01:03,  2.77s/it]  1%|          | 14/1337 [01:17<2:13:51,  6.07s/it]  1%|          | 15/1337 [01:19<1:44:02,  4.72s/it]  1%|          | 16/1337 [01:19<1:16:31,  3.48s/it]  1%|▏         | 17/1337 [07:11<39:37:49, 108.08s/it]