Unable to init server: Could not connect: Connection refused
Unable to init server: Impossible de se connecter : Connection refused

(main.py:31768): Gdk-CRITICAL **: 03:47:41.237: gdk_cursor_new_for_display: assertion 'GDK_IS_DISPLAY (display)' failed
Downloading: "https://download.pytorch.org/models/resnet101-63fe2227.pth" to /usr/users/gpusdi1/gpusdi1_49/.cache/torch/hub/checkpoints/resnet101-63fe2227.pth
  0%|          | 0.00/171M [00:00<?, ?B/s]  2%|▏         | 2.60M/171M [00:00<00:06, 27.3MB/s]  6%|▋         | 10.9M/171M [00:00<00:04, 33.9MB/s] 11%|█         | 18.8M/171M [00:00<00:03, 40.8MB/s] 16%|█▌        | 27.0M/171M [00:00<00:03, 48.4MB/s] 20%|██        | 34.4M/171M [00:00<00:02, 54.6MB/s] 24%|██▍       | 41.7M/171M [00:00<00:02, 59.8MB/s] 29%|██▊       | 48.9M/171M [00:00<00:02, 63.7MB/s] 33%|███▎      | 55.5M/171M [00:00<00:01, 65.2MB/s] 37%|███▋      | 63.6M/171M [00:00<00:01, 70.0MB/s] 42%|████▏     | 70.9M/171M [00:01<00:01, 71.9MB/s] 46%|████▌     | 78.2M/171M [00:01<00:01, 73.2MB/s] 50%|█████     | 85.5M/171M [00:01<00:01, 74.0MB/s] 54%|█████▍    | 92.7M/171M [00:01<00:01, 70.2MB/s] 59%|█████▉    | 101M/171M [00:01<00:00, 74.0MB/s]  64%|██████▍   | 110M/171M [00:01<00:00, 77.2MB/s] 69%|██████▊   | 117M/171M [00:01<00:00, 77.4MB/s] 73%|███████▎  | 125M/171M [00:01<00:00, 77.2MB/s] 77%|███████▋  | 132M/171M [00:01<00:00, 76.9MB/s] 82%|████████▏ | 139M/171M [00:01<00:00, 75.5MB/s] 86%|████████▌ | 147M/171M [00:02<00:00, 73.9MB/s] 91%|█████████ | 155M/171M [00:02<00:00, 75.4MB/s] 95%|█████████▌| 162M/171M [00:02<00:00, 51.6MB/s] 99%|█████████▊| 168M/171M [00:02<00:00, 46.1MB/s]100%|██████████| 171M/171M [00:02<00:00, 67.7MB/s]
  0%|          | 0/10693 [00:00<?, ?it/s]
Traceback (most recent call last):
  File "../main.py", line 134, in <module>
    handler.train(train_loader)
  File "/usr/users/gpusdi1/gpusdi1_49/Bureau/Challenge_kaggle/Challenge_plancton/Utilities/models.py", line 97, in train
    outputs = self.model(inputs)
  File "/usr/local/lib/python3.6/dist-packages/torch/nn/modules/module.py", line 1051, in _call_impl
    return forward_call(*input, **kwargs)
  File "/usr/users/gpusdi1/gpusdi1_49/Bureau/Challenge_kaggle/Challenge_plancton/Utilities/models.py", line 391, in forward
    x = self.conv_model(x).view(x.size(dim=0), -1)
  File "/usr/local/lib/python3.6/dist-packages/torch/nn/modules/module.py", line 1051, in _call_impl
    return forward_call(*input, **kwargs)
  File "/usr/local/lib/python3.6/dist-packages/torchvision/models/resnet.py", line 249, in forward
    return self._forward_impl(x)
  File "/usr/local/lib/python3.6/dist-packages/torchvision/models/resnet.py", line 239, in _forward_impl
    x = self.layer3(x)
  File "/usr/local/lib/python3.6/dist-packages/torch/nn/modules/module.py", line 1051, in _call_impl
    return forward_call(*input, **kwargs)
  File "/usr/local/lib/python3.6/dist-packages/torch/nn/modules/container.py", line 139, in forward
    input = module(input)
  File "/usr/local/lib/python3.6/dist-packages/torch/nn/modules/module.py", line 1051, in _call_impl
    return forward_call(*input, **kwargs)
  File "/usr/local/lib/python3.6/dist-packages/torchvision/models/resnet.py", line 132, in forward
    out = self.conv3(out)
  File "/usr/local/lib/python3.6/dist-packages/torch/nn/modules/module.py", line 1051, in _call_impl
    return forward_call(*input, **kwargs)
  File "/usr/local/lib/python3.6/dist-packages/torch/nn/modules/conv.py", line 443, in forward
    return self._conv_forward(input, self.weight, self.bias)
  File "/usr/local/lib/python3.6/dist-packages/torch/nn/modules/conv.py", line 440, in _conv_forward
    self.padding, self.dilation, self.groups)
RuntimeError: CUDA out of memory. Tried to allocate 92.00 MiB (GPU 0; 10.91 GiB total capacity; 9.85 GiB already allocated; 10.50 MiB free; 10.05 GiB reserved in total by PyTorch)
