Unable to init server: Could not connect: Connection refused
Unable to init server: Impossible de se connecterÂ : Connection refused

(model.py:537): Gdk-CRITICAL **: 14:26:31.392: gdk_cursor_new_for_display: assertion 'GDK_IS_DISPLAY (display)' failed
Traceback (most recent call last):
  File "model.py", line 149, in <module>
    fig = plt.figure(figsize=(20, 5), facecolor='w')
  File "/usr/local/lib/python3.6/dist-packages/matplotlib/pyplot.py", line 677, in figure
    **kwargs)
  File "/usr/local/lib/python3.6/dist-packages/matplotlib/pyplot.py", line 299, in new_figure_manager
    return _backend_mod.new_figure_manager(*args, **kwargs)
  File "/usr/local/lib/python3.6/dist-packages/matplotlib/backend_bases.py", line 3494, in new_figure_manager
    return cls.new_figure_manager_given_figure(num, fig)
  File "/usr/local/lib/python3.6/dist-packages/matplotlib/backends/_backend_tk.py", line 868, in new_figure_manager_given_figure
    window = tk.Tk(className="matplotlib")
  File "/usr/lib/python3.6/tkinter/__init__.py", line 2023, in __init__
    self.tk = _tkinter.create(screenName, baseName, className, interactive, wantobjects, useTk, sync, use)
_tkinter.TclError: couldn't connect to display ":9.0"
